[2024-12-06T13:32:28.790+0000] {local_task_job_runner.py:123} INFO - ::group::Pre task execution logs
[2024-12-06T13:32:28.819+0000] {taskinstance.py:2613} INFO - Dependencies all met for dep_context=non-requeueable deps ti=<TaskInstance: weather_data_pipeline.fetch_raw_weather_data manual__2024-12-06T13:27:18.535867+00:00 [queued]>
[2024-12-06T13:32:28.835+0000] {taskinstance.py:2613} INFO - Dependencies all met for dep_context=requeueable deps ti=<TaskInstance: weather_data_pipeline.fetch_raw_weather_data manual__2024-12-06T13:27:18.535867+00:00 [queued]>
[2024-12-06T13:32:28.836+0000] {taskinstance.py:2866} INFO - Starting attempt 2 of 2
[2024-12-06T13:32:28.894+0000] {taskinstance.py:2889} INFO - Executing <Task(PythonOperator): fetch_raw_weather_data> on 2024-12-06 13:27:18.535867+00:00
[2024-12-06T13:32:28.908+0000] {standard_task_runner.py:72} INFO - Started process 152 to run task
[2024-12-06T13:32:28.935+0000] {standard_task_runner.py:104} INFO - Running: ['airflow', 'tasks', 'run', 'weather_data_pipeline', 'fetch_raw_weather_data', 'manual__2024-12-06T13:27:18.535867+00:00', '--job-id', '5', '--raw', '--subdir', 'DAGS_FOLDER/dag.py', '--cfg-path', '/tmp/tmpwzljq46s']
[2024-12-06T13:32:28.947+0000] {standard_task_runner.py:105} INFO - Job 5: Subtask fetch_raw_weather_data
[2024-12-06T13:32:29.260+0000] {task_command.py:467} INFO - Running <TaskInstance: weather_data_pipeline.fetch_raw_weather_data manual__2024-12-06T13:27:18.535867+00:00 [running]> on host e4aacaa7d0d8
[2024-12-06T13:32:29.591+0000] {taskinstance.py:3132} INFO - Exporting env vars: AIRFLOW_CTX_DAG_OWNER='airflow' AIRFLOW_CTX_DAG_ID='weather_data_pipeline' AIRFLOW_CTX_TASK_ID='fetch_raw_weather_data' AIRFLOW_CTX_EXECUTION_DATE='2024-12-06T13:27:18.535867+00:00' AIRFLOW_CTX_TRY_NUMBER='2' AIRFLOW_CTX_DAG_RUN_ID='manual__2024-12-06T13:27:18.535867+00:00'
[2024-12-06T13:32:29.594+0000] {taskinstance.py:731} INFO - ::endgroup::
[2024-12-06T13:32:29.731+0000] {logging_mixin.py:190} INFO - Error occurred while fetching weather data: Command '['python', 'C:\\Users\\User\\Documents\\MLOPS-CLASS-TASK-7\\fetch_weather.py']' returned non-zero exit status 2.
[2024-12-06T13:32:29.732+0000] {taskinstance.py:3311} ERROR - Task failed with exception
Traceback (most recent call last):
  File "/home/airflow/.local/lib/python3.12/site-packages/airflow/models/taskinstance.py", line 767, in _execute_task
    result = _execute_callable(context=context, **execute_callable_kwargs)
             ^^^^^^^^^^^^^^^^^^^^^^^^^^^^^^^^^^^^^^^^^^^^^^^^^^^^^^^^^^^^^
  File "/home/airflow/.local/lib/python3.12/site-packages/airflow/models/taskinstance.py", line 733, in _execute_callable
    return ExecutionCallableRunner(
           ^^^^^^^^^^^^^^^^^^^^^^^^
  File "/home/airflow/.local/lib/python3.12/site-packages/airflow/utils/operator_helpers.py", line 252, in run
    return self.func(*args, **kwargs)
           ^^^^^^^^^^^^^^^^^^^^^^^^^^
  File "/home/airflow/.local/lib/python3.12/site-packages/airflow/models/baseoperator.py", line 417, in wrapper
    return func(self, *args, **kwargs)
           ^^^^^^^^^^^^^^^^^^^^^^^^^^^
  File "/home/airflow/.local/lib/python3.12/site-packages/airflow/operators/python.py", line 238, in execute
    return_value = self.execute_callable()
                   ^^^^^^^^^^^^^^^^^^^^^^^
  File "/home/airflow/.local/lib/python3.12/site-packages/airflow/operators/python.py", line 256, in execute_callable
    return runner.run(*self.op_args, **self.op_kwargs)
           ^^^^^^^^^^^^^^^^^^^^^^^^^^^^^^^^^^^^^^^^^^^
  File "/home/airflow/.local/lib/python3.12/site-packages/airflow/utils/operator_helpers.py", line 252, in run
    return self.func(*args, **kwargs)
           ^^^^^^^^^^^^^^^^^^^^^^^^^^
  File "/opt/airflow/dags/dag.py", line 9, in fetch_weather_data
    subprocess.run(
  File "/usr/local/lib/python3.12/subprocess.py", line 571, in run
    raise CalledProcessError(retcode, process.args,
subprocess.CalledProcessError: Command '['python', 'C:\\Users\\User\\Documents\\MLOPS-CLASS-TASK-7\\fetch_weather.py']' returned non-zero exit status 2.
[2024-12-06T13:32:29.751+0000] {taskinstance.py:1225} INFO - Marking task as FAILED. dag_id=weather_data_pipeline, task_id=fetch_raw_weather_data, run_id=manual__2024-12-06T13:27:18.535867+00:00, execution_date=20241206T132718, start_date=20241206T133228, end_date=20241206T133229
[2024-12-06T13:32:29.810+0000] {taskinstance.py:340} INFO - ::group::Post task execution logs
[2024-12-06T13:32:29.811+0000] {standard_task_runner.py:124} ERROR - Failed to execute job 5 for task fetch_raw_weather_data (Command '['python', 'C:\\Users\\User\\Documents\\MLOPS-CLASS-TASK-7\\fetch_weather.py']' returned non-zero exit status 2.; 152)
Traceback (most recent call last):
  File "/home/airflow/.local/lib/python3.12/site-packages/airflow/task/task_runner/standard_task_runner.py", line 117, in _start_by_fork
    ret = args.func(args, dag=self.dag)
          ^^^^^^^^^^^^^^^^^^^^^^^^^^^^^
  File "/home/airflow/.local/lib/python3.12/site-packages/airflow/cli/cli_config.py", line 49, in command
    return func(*args, **kwargs)
           ^^^^^^^^^^^^^^^^^^^^^
  File "/home/airflow/.local/lib/python3.12/site-packages/airflow/utils/cli.py", line 116, in wrapper
    return f(*args, **kwargs)
           ^^^^^^^^^^^^^^^^^^
  File "/home/airflow/.local/lib/python3.12/site-packages/airflow/cli/commands/task_command.py", line 483, in task_run
    task_return_code = _run_task_by_selected_method(args, _dag, ti)
                       ^^^^^^^^^^^^^^^^^^^^^^^^^^^^^^^^^^^^^^^^^^^^
  File "/home/airflow/.local/lib/python3.12/site-packages/airflow/cli/commands/task_command.py", line 256, in _run_task_by_selected_method
    return _run_raw_task(args, ti)
           ^^^^^^^^^^^^^^^^^^^^^^^
  File "/home/airflow/.local/lib/python3.12/site-packages/airflow/cli/commands/task_command.py", line 341, in _run_raw_task
    return ti._run_raw_task(
           ^^^^^^^^^^^^^^^^^
  File "/home/airflow/.local/lib/python3.12/site-packages/airflow/utils/session.py", line 97, in wrapper
    return func(*args, session=session, **kwargs)
           ^^^^^^^^^^^^^^^^^^^^^^^^^^^^^^^^^^^^^^
  File "/home/airflow/.local/lib/python3.12/site-packages/airflow/models/taskinstance.py", line 3005, in _run_raw_task
    return _run_raw_task(
           ^^^^^^^^^^^^^^
  File "/home/airflow/.local/lib/python3.12/site-packages/airflow/models/taskinstance.py", line 273, in _run_raw_task
    TaskInstance._execute_task_with_callbacks(
  File "/home/airflow/.local/lib/python3.12/site-packages/airflow/models/taskinstance.py", line 3159, in _execute_task_with_callbacks
    result = self._execute_task(context, task_orig)
             ^^^^^^^^^^^^^^^^^^^^^^^^^^^^^^^^^^^^^^
  File "/home/airflow/.local/lib/python3.12/site-packages/airflow/models/taskinstance.py", line 3183, in _execute_task
    return _execute_task(self, context, task_orig)
           ^^^^^^^^^^^^^^^^^^^^^^^^^^^^^^^^^^^^^^^
  File "/home/airflow/.local/lib/python3.12/site-packages/airflow/models/taskinstance.py", line 767, in _execute_task
    result = _execute_callable(context=context, **execute_callable_kwargs)
             ^^^^^^^^^^^^^^^^^^^^^^^^^^^^^^^^^^^^^^^^^^^^^^^^^^^^^^^^^^^^^
  File "/home/airflow/.local/lib/python3.12/site-packages/airflow/models/taskinstance.py", line 733, in _execute_callable
    return ExecutionCallableRunner(
           ^^^^^^^^^^^^^^^^^^^^^^^^
  File "/home/airflow/.local/lib/python3.12/site-packages/airflow/utils/operator_helpers.py", line 252, in run
    return self.func(*args, **kwargs)
           ^^^^^^^^^^^^^^^^^^^^^^^^^^
  File "/home/airflow/.local/lib/python3.12/site-packages/airflow/models/baseoperator.py", line 417, in wrapper
    return func(self, *args, **kwargs)
           ^^^^^^^^^^^^^^^^^^^^^^^^^^^
  File "/home/airflow/.local/lib/python3.12/site-packages/airflow/operators/python.py", line 238, in execute
    return_value = self.execute_callable()
                   ^^^^^^^^^^^^^^^^^^^^^^^
  File "/home/airflow/.local/lib/python3.12/site-packages/airflow/operators/python.py", line 256, in execute_callable
    return runner.run(*self.op_args, **self.op_kwargs)
           ^^^^^^^^^^^^^^^^^^^^^^^^^^^^^^^^^^^^^^^^^^^
  File "/home/airflow/.local/lib/python3.12/site-packages/airflow/utils/operator_helpers.py", line 252, in run
    return self.func(*args, **kwargs)
           ^^^^^^^^^^^^^^^^^^^^^^^^^^
  File "/opt/airflow/dags/dag.py", line 9, in fetch_weather_data
    subprocess.run(
  File "/usr/local/lib/python3.12/subprocess.py", line 571, in run
    raise CalledProcessError(retcode, process.args,
subprocess.CalledProcessError: Command '['python', 'C:\\Users\\User\\Documents\\MLOPS-CLASS-TASK-7\\fetch_weather.py']' returned non-zero exit status 2.
[2024-12-06T13:32:29.878+0000] {local_task_job_runner.py:266} INFO - Task exited with return code 1
[2024-12-06T13:32:29.907+0000] {taskinstance.py:3895} INFO - 0 downstream tasks scheduled from follow-on schedule check
[2024-12-06T13:32:29.941+0000] {local_task_job_runner.py:245} INFO - ::endgroup::
